Workbook

Sheet Comsuption
A1: Algorithm | B1: Consumption(mW) | C1: Consumption(mW) | D1: Consumption(mW) | E1: Consumption(mW) | F1: Consumption(mW) | G1: Consumption(mW) | H1: Consumption(mW) | I1: Consumption(mW) | J1: Consumption(mW) | K1: Consumption(mW) | R1: AVG | V1: ENCRYPT | W1: mW | Y1: 10 | Z1: 100 | AA1: 200 | AC1: ENCRYPT | AD1: mS | AF1: 10 | AG1: 100 | AH1: 200 | AJ1: ENCRYPT | AK1: mJ | AM1: 10 | AN1: 100 | AO1: 200
A2: E_AES_128_CBC_10_PKCS5Padding_1521404543009 | B2: 2 | C2: 0 | D2: 1 | E2: 2 | F2: 1 | G2: 1 | H2: 0 | I2: 0 | J2: 0 | K2: 0 | L2: 1 | M2: 1 | N2: 0 | O2: 1 | P2: 0 | R2: =AVERAGE(B2:Q2) -> 0.66666667 | S2: CBC PKCS5 | V2: 128 | W2: ECB | X2: PKCS5 | Y2: =R8 -> 0.2 | Z2: =R39 -> 0.066666667 | AA2: =R70 -> 0.46666667 | AC2: 128 | AD2: ECB | AE2: PKCS5 | AF2: 61.7 | AG2: 62.9 | AH2: 80.8 | AJ2: 128 | AK2: ECB | AL2: PKCS5 | AM2: =Y2*AF2 -> 12.34 | AN2: =Z2*AG2 -> 4.1933333 | AO2: =AA2*AH2 -> 37.706667
A3: E_AES_192_CBC_10_PKCS5Padding_1521404543009 | B3: 1 | C3: 0 | D3: 0 | E3: 0 | F3: 1 | G3: 0 | H3: 0 | I3: 0 | J3: 0 | K3: 0 | L3: 0 | M3: 0 | N3: 0 | O3: 0 | P3: 0 | R3: =AVERAGE(B3:Q3) -> 0.13333333 | X3: ZERO | Y3: =R11 -> 0.13333333 | Z3: =R42 -> 0.53333333 | AA3: =R73 -> 0.66666667 | AE3: ZERO | AF3: 71.7 | AG3: 63.8 | AH3: 71.5 | AL3: ZERO | AM3: =Y3*AF3 -> 9.56 | AN3: =Z3*AG3 -> 34.026667 | AO3: =AA3*AH3 -> 47.666667
A4: E_AES_256_CBC_10_PKCS5Padding_1521404543009 | B4: 0 | C4: 0 | D4: 1 | E4: 0 | F4: 0 | G4: 0 | H4: 0 | I4: 0 | J4: 0 | K4: 0 | L4: 0 | M4: 0 | N4: 0 | O4: 0 | P4: 0 | R4: =AVERAGE(B4:Q4) -> 0.066666667 | W4: CBC | X4: PKCS5 | Y4: =R2 -> 0.66666667 | Z4: =R33 -> 0.6 | AA4: =R64 -> 0.66666667 | AD4: CBC | AE4: PKCS5 | AF4: 54.4 | AG4: 55.2 | AH4: 49 | AK4: CBC | AL4: PKCS5 | AM4: =Y4*AF4 -> 36.266667 | AN4: =Z4*AG4 -> 33.12 | AO4: =AA4*AH4 -> 32.666667
A5: E_AES_128_CBC_10_ZeroBytePadding_1521404543009 | B5: 0 | C5: 1 | D5: 0 | E5: 0 | F5: 0 | G5: 1 | H5: 1 | I5: 0 | J5: 0 | K5: 0 | L5: 0 | M5: 0 | N5: 0 | O5: 0 | P5: 0 | R5: =AVERAGE(B5:Q5) -> 0.2 | S5: CBC ZERO | X5: ZERO | Y5: =R5 -> 0.2 | Z5: =R36 -> 0.53333333 | AA5: =R67 -> 0.26666667 | AE5: ZERO | AF5: 65.3 | AG5: 77.6 | AH5: 78.7 | AL5: ZERO | AM5: =Y5*AF5 -> 13.06 | AN5: =Z5*AG5 -> 41.386667 | AO5: =AA5*AH5 -> 20.986667
A6: E_AES_192_CBC_10_ZeroBytePadding_1521404543009 | B6: 0 | C6: 0 | D6: 0 | E6: 1 | F6: 0 | G6: 0 | H6: 0 | I6: 1 | J6: 0 | K6: 0 | L6: 1 | M6: 1 | N6: 0 | O6: 1 | P6: 0 | R6: =AVERAGE(B6:Q6) -> 0.33333333 | V6: 192 | W6: ECB | X6: PKCS5 | Y6: =R9 -> 0.066666667 | Z6: =R40 -> 0.4 | AA6: =R71 -> 0.33333333 | AC6: 192 | AD6: ECB | AE6: PKCS5 | AF6: 64.1 | AG6: 62.5 | AH6: 60.8 | AJ6: 192 | AK6: ECB | AL6: PKCS5 | AM6: =Y6*AF6 -> 4.2733333 | AN6: =Z6*AG6 -> 25 | AO6: =AA6*AH6 -> 20.266667
A7: E_AES_256_CBC_10_ZeroBytePadding_1521404543009 | B7: 0 | C7: 0 | D7: 0 | E7: 2 | F7: 0 | G7: 1 | H7: 0 | I7: 0 | J7: 0 | K7: 0 | L7: 0 | M7: 0 | N7: 1 | O7: 0 | P7: 0 | R7: =AVERAGE(B7:Q7) -> 0.26666667 | X7: ZERO | Y7: =R12 -> 0 | Z7: =R43 -> 0.4 | AA7: =R74 -> 0.46666667 | AE7: ZERO | AF7: 65.2 | AG7: 70.8 | AH7: 61.8 | AL7: ZERO | AM7: =Y7*AF7 -> 0 | AN7: =Z7*AG7 -> 28.32 | AO7: =AA7*AH7 -> 28.84
A8: E_AES_128_ECB_10_PKCS5Padding_1521404543009 | B8: 0 | C8: 0 | D8: 0 | E8: 2 | F8: 0 | G8: 0 | H8: 0 | I8: 0 | J8: 1 | K8: 0 | L8: 0 | M8: 0 | N8: 0 | O8: 0 | P8: 0 | R8: =AVERAGE(B8:Q8) -> 0.2 | S8: ECB PKCS5 | W8: CBC | X8: PKCS5 | Y8: =R3 -> 0.13333333 | Z8: =R34 -> 0.46666667 | AA8: =R65 -> 0.46666667 | AD8: CBC | AE8: PKCS5 | AF8: 59 | AG8: 68.2 | AH8: 76.5 | AK8: CBC | AL8: PKCS5 | AM8: =Y8*AF8 -> 7.8666667 | AN8: =Z8*AG8 -> 31.826667 | AO8: =AA8*AH8 -> 35.7
A9: E_AES_192_ECB_10_PKCS5Padding_1521404543009 | B9: 1 | C9: 0 | D9: 0 | E9: 0 | F9: 0 | G9: 0 | H9: 0 | I9: 0 | J9: 0 | K9: 0 | L9: 0 | M9: 0 | N9: 0 | O9: 0 | P9: 0 | R9: =AVERAGE(B9:Q9) -> 0.066666667 | X9: ZERO | Y9: =R6 -> 0.33333333 | Z9: =R37 -> 0.6 | AA9: =R68 -> 0.46666667 | AE9: ZERO | AF9: 74.2 | AG9: 63.4 | AH9: 66.8 | AL9: ZERO | AM9: =Y9*AF9 -> 24.733333 | AN9: =Z9*AG9 -> 38.04 | AO9: =AA9*AH9 -> 31.173333
A10: E_AES_256_ECB_10_PKCS5Padding_1521404543009 | B10: 0 | C10: 1 | D10: 0 | E10: 0 | F10: 0 | G10: 0 | H10: 0 | I10: 0 | J10: 0 | K10: 0 | L10: 1 | M10: 1 | N10: 0 | O10: 0 | P10: 0 | R10: =AVERAGE(B10:Q10) -> 0.2 | V10: 256 | W10: ECB | X10: PKCS5 | Y10: =R10 -> 0.2 | Z10: =R41 -> 0.6 | AA10: =R72 -> 0.4 | AC10: 256 | AD10: ECB | AE10: PKCS5 | AF10: 72.1 | AG10: 61.8 | AH10: 64.5 | AJ10: 256 | AK10: ECB | AL10: PKCS5 | AM10: =Y10*AF10 -> 14.42 | AN10: =Z10*AG10 -> 37.08 | AO10: =AA10*AH10 -> 25.8
A11: E_AES_128_ECB_10_ZeroBytePadding_1521404543009 | B11: 0 | C11: 0 | D11: 0 | E11: 0 | F11: 1 | G11: 0 | H11: 0 | I11: 0 | J11: 0 | K11: 1 | L11: 0 | M11: 0 | N11: 0 | O11: 0 | P11: 0 | R11: =AVERAGE(B11:Q11) -> 0.13333333 | S11: ECB Zero | X11: ZERO | Y11: =R13 -> 0.066666667 | Z11: =R44 -> 0.6 | AA11: =R75 -> 1 | AE11: ZERO | AF11: 71 | AG11: 56.9 | AH11: 73.8 | AL11: ZERO | AM11: =Y11*AF11 -> 4.7333333 | AN11: =Z11*AG11 -> 34.14 | AO11: =AA11*AH11 -> 73.8
A12: E_AES_192_ECB_10_ZeroBytePadding_1521404543009 | B12: 0 | C12: 0 | D12: 0 | E12: 0 | F12: 0 | G12: 0 | H12: 0 | I12: 0 | J12: 0 | K12: 0 | L12: 0 | M12: 0 | N12: 0 | O12: 0 | P12: 0 | R12: =AVERAGE(B12:Q12) -> 0 | W12: CBC | X12: PKCS5 | Y12: =R4 -> 0.066666667 | Z12: =R35 -> 0.2 | AA12: =R66 -> 0.53333333 | AD12: CBC | AE12: PKCS5 | AF12: 57.2 | AG12: 61.9 | AH12: 70.4 | AK12: CBC | AL12: PKCS5 | AM12: =Y12*AF12 -> 3.8133333 | AN12: =Z12*AG12 -> 12.38 | AO12: =AA12*AH12 -> 37.546667
A13: E_AES_256_ECB_10_ZeroBytePadding_1521404543009 | B13: 0 | C13: 0 | D13: 0 | E13: 1 | F13: 0 | G13: 0 | H13: 0 | I13: 0 | J13: 0 | K13: 0 | L13: 0 | M13: 0 | N13: 0 | O13: 0 | P13: 0 | R13: =AVERAGE(B13:Q13) -> 0.066666667 | X13: ZERO | Y13: =R7 -> 0.26666667 | Z13: =R38 -> 0.6 | AA13: =R69 -> 0.4 | AE13: ZERO | AF13: 64.5 | AG13: 60.3 | AH13: 61.9 | AL13: ZERO | AM13: =Y13*AF13 -> 17.2 | AN13: =Z13*AG13 -> 36.18 | AO13: =AA13*AH13 -> 24.76
A16: Algorithm | B16: Consumption(mW) | C16: Consumption(mW) | D16: Consumption(mW) | E16: Consumption(mW) | F16: Consumption(mW) | G16: Consumption(mW) | H16: Consumption(mW) | I16: Consumption(mW) | J16: Consumption(mW) | K16: Consumption(mW) | R16: AVG | V16: DECRYPT | W16: mW | Y16: 10 | Z16: 100 | AA16: 200 | AC16: DECRYPT | AD16: mS | AF16: 10 | AG16: 100 | AH16: 200 | AJ16: DECRYPT | AK16: mJ | AM16: 10 | AN16: 100 | AO16: 200
A17: D_AES_128_CBC_10_PKCS5Padding_1521404635390 | B17: 0 | C17: 2 | D17: 1 | E17: 0 | F17: 1 | G17: 1 | H17: 0 | I17: 0 | J17: 0 | K17: 0 | R17: =AVERAGE(B17:Q17) -> 0.5 | S17: CBC PKCS5 | V17: 128 | W17: ECB | X17: PKCS5 | Y17: =R23 -> 0.3 | Z17: =R54 -> 0.6 | AA17: =R85 -> 0.6 | AC17: 128 | AD17: ECB | AE17: PKCS5 | AF17: 64.8 | AG17: 66 | AH17: 61.2 | AJ17: 128 | AK17: ECB | AL17: PKCS5 | AM17: =AF17*Y17 -> 19.44 | AN17: =AG17*Z17 -> 39.6 | AO17: =AH17*AA17 -> 36.72
A18: D_AES_192_CBC_10_PKCS5Padding_1521404635390 | B18: 1 | C18: 0 | D18: 0 | E18: 0 | F18: 0 | G18: 1 | H18: 0 | I18: 0 | J18: 0 | K18: 0 | R18: =AVERAGE(B18:Q18) -> 0.2 | X18: ZERO | Y18: =R26 -> 0 | Z18: =R57 -> 0.5 | AA18: =R88 -> 0.9 | AE18: ZERO | AF18: 59.2 | AG18: 62 | AH18: 65.2 | AL18: ZERO | AM18: 0 | AN18: =AG18*Z18 -> 31 | AO18: =AH18*AA18 -> 58.68
A19: D_AES_256_CBC_10_PKCS5Padding_1521404635390 | B19: 1 | C19: 1 | D19: 0 | E19: 0 | F19: 0 | G19: 1 | H19: 0 | I19: 0 | J19: 0 | K19: 1 | R19: =AVERAGE(B19:Q19) -> 0.4 | W19: CBC | X19: PKCS5 | Y19: =R17 -> 0.5 | Z19: =R48 -> 0.2 | AA19: =R79 -> 0.2 | AD19: CBC | AE19: PKCS5 | AF19: 51.6 | AG19: 54.7 | AH19: 57.4 | AK19: CBC | AL19: PKCS5 | AM19: =AF19*Y19 -> 25.8 | AN19: =AG19*Z19 -> 10.94 | AO19: =AH19*AA19 -> 11.48
A20: D_AES_128_CBC_10_ZeroBytePadding_1521404635390 | B20: 0 | C20: 0 | D20: 0 | E20: 0 | F20: 0 | G20: 2 | H20: 0 | I20: 1 | J20: 0 | K20: 0 | R20: =AVERAGE(B20:Q20) -> 0.3 | S20: CBC ZERO | X20: ZERO | Y20: =R20 -> 0.3 | Z20: =R51 -> 0.4 | AA20: =R82 -> 0.5 | AE20: ZERO | AF20: 73.8 | AG20: 71 | AH20: 58.2 | AL20: ZERO | AM20: =AF20*Y20 -> 22.14 | AN20: =AG20*Z20 -> 28.4 | AO20: =AH20*AA20 -> 29.1
A21: D_AES_192_CBC_10_ZeroBytePadding_1521404635390 | B21: 0 | C21: 0 | D21: 1 | E21: 0 | F21: 0 | G21: 0 | H21: 0 | I21: 0 | J21: 0 | K21: 0 | R21: =AVERAGE(B21:Q21) -> 0.1 | V21: 192 | W21: ECB | X21: PKCS5 | Y21: =R24 -> 0.1 | Z21: =R55 -> 0.8 | AA21: =R86 -> 0.7 | AC21: 192 | AD21: ECB | AE21: PKCS5 | AF21: 61.5 | AG21: 61.5 | AH21: 65.1 | AJ21: 192 | AK21: ECB | AL21: PKCS5 | AM21: =AF21*Y21 -> 6.15 | AN21: =AG21*Z21 -> 49.2 | AO21: =AH21*AA21 -> 45.57
A22: D_AES_256_CBC_10_ZeroBytePadding_1521404635390 | B22: 1 | C22: 1 | D22: 0 | E22: 0 | F22: 0 | G22: 0 | H22: 1 | I22: 1 | J22: 0 | K22: 1 | R22: =AVERAGE(B22:Q22) -> 0.5 | X22: ZERO | Y22: =R27 -> 0.1 | Z22: =R58 -> 0.3 | AA22: =R89 -> 0.5 | AE22: ZERO | AF22: 69.4 | AG22: 52.8 | AH22: 65.5 | AL22: ZERO | AM22: =AF22*Y22 -> 6.94 | AN22: =AG22*Z22 -> 15.84 | AO22: =AH22*AA22 -> 32.75
A23: D_AES_128_ECB_10_PKCS5Padding_1521404635390 | B23: 0 | C23: 0 | D23: 0 | E23: 3 | F23: 0 | G23: 0 | H23: 0 | I23: 0 | J23: 0 | K23: 0 | R23: =AVERAGE(B23:Q23) -> 0.3 | S23: ECB PKCS5 | W23: CBC | X23: PKCS5 | Y23: =R18 -> 0.2 | Z23: =R49 -> 0.5 | AA23: =R80 -> 0.4 | AD23: CBC | AE23: PKCS5 | AF23: 64.1 | AG23: 74.1 | AH23: 61.4 | AK23: CBC | AL23: PKCS5 | AM23: =AF23*Y23 -> 12.82 | AN23: =AG23*Z23 -> 37.05 | AO23: =AH23*AA23 -> 24.56
A24: D_AES_192_ECB_10_PKCS5Padding_1521404635390 | B24: 1 | C24: 0 | D24: 0 | E24: 0 | F24: 0 | G24: 0 | H24: 0 | I24: 0 | J24: 0 | K24: 0 | R24: =AVERAGE(B24:Q24) -> 0.1 | X24: ZERO | Y24: =R21 -> 0.1 | Z24: =R52 -> 0.6 | AA24: =R83 -> 1 | AE24: ZERO | AF24: 61.7 | AG24: 66.2 | AH24: 71.8 | AL24: ZERO | AM24: =AF24*Y24 -> 6.17 | AN24: =AG24*Z24 -> 39.72 | AO24: =AH24*AA24 -> 71.8
A25: D_AES_256_ECB_10_PKCS5Padding_1521404635390 | B25: 0 | C25: 1 | D25: 1 | E25: 0 | F25: 0 | G25: 0 | H25: 0 | I25: 0 | J25: 0 | K25: 0 | R25: =AVERAGE(B25:Q25) -> 0.2 | V25: 256 | W25: ECB | X25: PKCS5 | Y25: =R25 -> 0.2 | Z25: =R56 -> 1 | AA25: =R87 -> 1 | AC25: 256 | AD25: ECB | AE25: PKCS5 | AF25: 61.5 | AG25: 66.4 | AH25: 62.6 | AJ25: 256 | AK25: ECB | AL25: PKCS5 | AM25: =AF25*Y25 -> 12.3 | AN25: =AG25*Z25 -> 66.4 | AO25: =AH25*AA25 -> 62.6
A26: D_AES_128_ECB_10_ZeroBytePadding_1521404635390 | B26: 0 | C26: 0 | D26: 0 | E26: 0 | F26: 0 | G26: 0 | H26: 0 | I26: 0 | J26: 0 | K26: 0 | R26: =AVERAGE(B26:Q26) -> 0 | S26: ECB Zero | X26: ZERO | Y26: =R28 -> 0.1 | Z26: =R59 -> 0.6 | AA26: =R90 -> 0.9 | AE26: ZERO | AF26: 54.2 | AG26: 67.3 | AH26: 74.3 | AL26: ZERO | AM26: =AF26*Y26 -> 5.42 | AN26: =AG26*Z26 -> 40.38 | AO26: =AH26*AA26 -> 66.87
A27: D_AES_192_ECB_10_ZeroBytePadding_1521404635390 | B27: 0 | C27: 0 | D27: 0 | E27: 0 | F27: 0 | G27: 0 | H27: 1 | I27: 0 | J27: 0 | K27: 0 | R27: =AVERAGE(B27:Q27) -> 0.1 | W27: CBC | X27: PKCS5 | Y27: =R19 -> 0.4 | Z27: =R50 -> 0.5 | AA27: =R81 -> 0.6 | AD27: CBC | AE27: PKCS5 | AF27: 66.3 | AG27: 74.1 | AH27: 73.5 | AK27: CBC | AL27: PKCS5 | AM27: =AF27*Y27 -> 26.52 | AN27: =AG27*Z27 -> 37.05 | AO27: =AH27*AA27 -> 44.1
A28: D_AES_256_ECB_10_ZeroBytePadding_1521404635390 | B28: 0 | C28: 0 | D28: 0 | E28: 0 | F28: 0 | G28: 0 | H28: 0 | I28: 0 | J28: 0 | K28: 1 | R28: =AVERAGE(B28:Q28) -> 0.1 | X28: ZERO | Y28: =R22 -> 0.5 | Z28: =R53 -> 1.2 | AA28: =R84 -> 0.5 | AE28: ZERO | AF28: 66.6 | AG28: 59.7 | AH28: 65.6 | AL28: ZERO | AM28: =AF28*Y28 -> 33.3 | AN28: =AG28*Z28 -> 71.64 | AO28: =AH28*AA28 -> 32.8
A30: 100
A32: Algorithm | B32: Consumption(mW) | C32: Consumption(mW) | D32: Consumption(mW) | E32: Consumption(mW) | F32: Consumption(mW) | G32: Consumption(mW) | H32: Consumption(mW) | I32: Consumption(mW) | J32: Consumption(mW) | K32: Consumption(mW) | R32: AVG
A33: E_AES_128_CBC_100_PKCS5Padding_1521404733303 | B33: 1 | C33: 0 | D33: 1 | E33: 1 | F33: 0 | G33: 0 | H33: 0 | I33: 1 | J33: 1 | K33: 3 | L33: 1 | M33: 0 | N33: 0 | O33: 0 | P33: 0 | R33: =AVERAGE(B33:Q33) -> 0.6 | S33: CBC PKCS5
A34: E_AES_192_CBC_100_PKCS5Padding_1521404733303 | B34: 1 | C34: 0 | D34: 0 | E34: 1 | F34: 1 | G34: 0 | H34: 0 | I34: 0 | J34: 0 | K34: 0 | L34: 3 | M34: 0 | N34: 1 | O34: 0 | P34: 0 | R34: =AVERAGE(B34:Q34) -> 0.46666667
A35: E_AES_256_CBC_100_PKCS5Padding_1521404733303 | B35: 0 | C35: 0 | D35: 0 | E35: 0 | F35: 1 | G35: 1 | H35: 0 | I35: 0 | J35: 0 | K35: 0 | L35: 0 | M35: 0 | N35: 0 | O35: 0 | P35: 1 | R35: =AVERAGE(B35:Q35) -> 0.2
A36: E_AES_128_CBC_100_ZeroBytePadding_1521404733303 | B36: 0 | C36: 1 | D36: 1 | E36: 1 | F36: 1 | G36: 1 | H36: 1 | I36: 0 | J36: 0 | K36: 1 | L36: 0 | M36: 0 | N36: 0 | O36: 1 | P36: 0 | R36: =AVERAGE(B36:Q36) -> 0.53333333 | S36: CBC ZERO
A37: E_AES_192_CBC_100_ZeroBytePadding_1521404733303 | B37: 2 | C37: 0 | D37: 1 | E37: 0 | F37: 0 | G37: 1 | H37: 1 | I37: 1 | J37: 1 | K37: 0 | L37: 1 | M37: 0 | N37: 1 | O37: 0 | P37: 0 | R37: =AVERAGE(B37:Q37) -> 0.6
A38: E_AES_256_CBC_100_ZeroBytePadding_1521404733303 | B38: 2 | C38: 1 | D38: 1 | E38: 1 | F38: 0 | G38: 0 | H38: 1 | I38: 1 | J38: 0 | K38: 0 | L38: 0 | M38: 1 | N38: 0 | O38: 1 | P38: 0 | R38: =AVERAGE(B38:Q38) -> 0.6
A39: E_AES_128_ECB_100_PKCS5Padding_1521404733303 | B39: 0 | C39: 0 | D39: 0 | E39: 0 | F39: 1 | G39: 0 | H39: 0 | I39: 0 | J39: 0 | K39: 0 | L39: 0 | M39: 0 | N39: 0 | O39: 0 | P39: 0 | R39: =AVERAGE(B39:Q39) -> 0.066666667 | S39: ECB PKCS5
A40: E_AES_192_ECB_100_PKCS5Padding_1521404733303 | B40: 2 | C40: 0 | D40: 0 | E40: 0 | F40: 0 | G40: 2 | H40: 1 | I40: 0 | J40: 0 | K40: 0 | L40: 0 | M40: 0 | N40: 1 | O40: 0 | P40: 0 | R40: =AVERAGE(B40:Q40) -> 0.4
A41: E_AES_256_ECB_100_PKCS5Padding_1521404733303 | B41: 4 | C41: 0 | D41: 0 | E41: 0 | F41: 0 | G41: 2 | H41: 1 | I41: 1 | J41: 0 | K41: 0 | L41: 0 | M41: 0 | N41: 0 | O41: 1 | P41: 0 | R41: =AVERAGE(B41:Q41) -> 0.6
A42: E_AES_128_ECB_100_ZeroBytePadding_1521404733303 | B42: 2 | C42: 1 | D42: 1 | E42: 0 | F42: 1 | G42: 2 | H42: 0 | I42: 0 | J42: 0 | K42: 0 | L42: 0 | M42: 1 | N42: 0 | O42: 0 | P42: 0 | R42: =AVERAGE(B42:Q42) -> 0.53333333 | S42: ECB Zero
A43: E_AES_192_ECB_100_ZeroBytePadding_1521404733303 | B43: 2 | C43: 0 | D43: 0 | E43: 0 | F43: 0 | G43: 2 | H43: 0 | I43: 1 | J43: 1 | K43: 0 | L43: 0 | M43: 0 | N43: 0 | O43: 0 | P43: 0 | R43: =AVERAGE(B43:Q43) -> 0.4
A44: E_AES_256_ECB_100_ZeroBytePadding_1521404733303 | B44: 2 | C44: 0 | D44: 0 | E44: 1 | F44: 0 | G44: 4 | H44: 0 | I44: 0 | J44: 0 | K44: 1 | L44: 0 | M44: 0 | N44: 0 | O44: 1 | P44: 0 | R44: =AVERAGE(B44:Q44) -> 0.6
...

Sheet Time
A1: Algorithm | B1: Time(milliseconds) | C1: Time(milliseconds) | D1: Time(milliseconds) | E1: Time(milliseconds) | F1: Time(milliseconds) | G1: Time(milliseconds) | H1: Time(milliseconds) | I1: Time(milliseconds) | J1: Time(milliseconds) | K1: Time(milliseconds) | R1: AVG | V1: ENCRYPT | Y1: 10 | Z1: 100 | AA1: 200
A2: E_AES_128_CBC_10_PKCS5Padding_1521404543009 | B2: 25 | C2: 55 | D2: 61 | E2: 85 | F2: 52 | G2: 41 | H2: 63 | I2: 68 | J2: 49 | K2: 45 | L2: 39 | M2: 52 | N2: 42 | O2: 61 | P2: 53 | R2: =AVERAGE(B2:Q2) -> 52.733333 | S2: CBC PKCS5 | T2: 128 | V2: 128 | W2: ECB | X2: PKCS5 | Y2: =R8 -> 61.266667 | Z2: =R39 -> 62.666667 | AA2: =R70 -> 77.533333
A3: E_AES_192_CBC_10_PKCS5Padding_1521404543009 | B3: 67 | C3: 47 | D3: 43 | E3: 70 | F3: 84 | G3: 46 | H3: 51 | I3: 77 | J3: 62 | K3: 43 | L3: 90 | M3: 82 | N3: 62 | O3: 48 | P3: 53 | R3: =AVERAGE(B3:Q3) -> 61.666667 | T3: 192 | X3: ZERO | Y3: =R11 -> 70.333333 | Z3: =R42 -> 64.733333 | AA3: =R73 -> 72.466667
A4: E_AES_256_CBC_10_PKCS5Padding_1521404543009 | B4: 42 | C4: 72 | D4: 39 | E4: 44 | F4: 78 | G4: 52 | H4: 40 | I4: 62 | J4: 67 | K4: 76 | L4: 60 | M4: 64 | N4: 64 | O4: 88 | P4: 53 | R4: =AVERAGE(B4:Q4) -> 60.066667 | T4: 256 | W4: CBC | X4: PKCS5 | Y4: =R2 -> 52.733333 | Z4: =R33 -> 56.933333 | AA4: =R64 -> 51.2
A5: E_AES_128_CBC_10_ZeroBytePadding_1521404543009 | B5: 34 | C5: 65 | D5: 67 | E5: 67 | F5: 106 | G5: 56 | H5: 65 | I5: 66 | J5: 59 | K5: 68 | L5: 37 | M5: 90 | N5: 70 | O5: 70 | P5: 77 | R5: =AVERAGE(B5:Q5) -> 66.466667 | S5: CBC ZERO | X5: ZERO | Y5: =R5 -> 66.466667 | Z5: =R36 -> 74.066667 | AA5: =R67 -> 73
A6: E_AES_192_CBC_10_ZeroBytePadding_1521404543009 | B6: 59 | C6: 49 | D6: 153 | E6: 72 | F6: 76 | G6: 48 | H6: 95 | I6: 47 | J6: 73 | K6: 70 | L6: 59 | M6: 64 | N6: 39 | O6: 67 | P6: 76 | R6: =AVERAGE(B6:Q6) -> 69.8 | V6: 192 | W6: ECB | X6: PKCS5 | Y6: =R9 -> 62.8 | Z6: =R40 -> 64.866667 | AA6: =R71 -> 64.333333
A7: E_AES_256_CBC_10_ZeroBytePadding_1521404543009 | B7: 80 | C7: 55 | D7: 41 | E7: 57 | F7: 69 | G7: 69 | H7: 50 | I7: 73 | J7: 96 | K7: 55 | L7: 90 | M7: 73 | N7: 61 | O7: 67 | P7: 60 | R7: =AVERAGE(B7:Q7) -> 66.4 | X7: ZERO | Y7: =R12 -> 65.8 | Z7: =R43 -> 70.2 | AA7: =R74 -> 64.666667
A8: E_AES_128_ECB_10_PKCS5Padding_1521404543009 | B8: 72 | C8: 40 | D8: 41 | E8: 85 | F8: 66 | G8: 69 | H8: 48 | I8: 22 | J8: 82 | K8: 92 | L8: 47 | M8: 47 | N8: 72 | O8: 71 | P8: 65 | R8: =AVERAGE(B8:Q8) -> 61.266667 | S8: ECB PKCS5 | W8: CBC | X8: PKCS5 | Y8: =R3 -> 61.666667 | Z8: =R34 -> 65.933333 | AA8: =R65 -> 72.2
A9: E_AES_192_ECB_10_PKCS5Padding_1521404543009 | B9: 29 | C9: 91 | D9: 87 | E9: 43 | F9: 83 | G9: 55 | H9: 37 | I9: 62 | J9: 79 | K9: 75 | L9: 34 | M9: 67 | N9: 67 | O9: 71 | P9: 62 | R9: =AVERAGE(B9:Q9) -> 62.8 | X9: ZERO | Y9: =R6 -> 69.8 | Z9: =R37 -> 62.333333 | AA9: =R68 -> 64
A10: E_AES_256_ECB_10_PKCS5Padding_1521404543009 | B10: 95 | C10: 64 | D10: 55 | E10: 20 | F10: 77 | G10: 73 | H10: 99 | I10: 66 | J10: 80 | K10: 92 | L10: 92 | M10: 67 | N10: 70 | O10: 91 | P10: 73 | R10: =AVERAGE(B10:Q10) -> 74.266667 | V10: 256 | W10: ECB | X10: PKCS5 | Y10: =R10 -> 74.266667 | Z10: =R41 -> 62.733333 | AA10: =R72 -> 65.6
A11: E_AES_128_ECB_10_ZeroBytePadding_1521404543009 | B11: 25 | C11: 82 | D11: 89 | E11: 74 | F11: 80 | G11: 44 | H11: 91 | I11: 64 | J11: 74 | K11: 94 | L11: 62 | M11: 57 | N11: 73 | O11: 75 | P11: 71 | R11: =AVERAGE(B11:Q11) -> 70.333333 | S11: ECB Zero | X11: ZERO | Y11: =R13 -> 71.466667 | Z11: =R44 -> 62.2 | AA11: =R75 -> 74.866667
A12: E_AES_192_ECB_10_ZeroBytePadding_1521404543009 | B12: 35 | C12: 81 | D12: 34 | E12: 71 | F12: 71 | G12: 75 | H12: 74 | I12: 82 | J12: 66 | K12: 63 | L12: 47 | M12: 70 | N12: 74 | O12: 67 | P12: 77 | R12: =AVERAGE(B12:Q12) -> 65.8 | W12: CBC | X12: PKCS5 | Y12: =R4 -> 60.066667 | Z12: =R35 -> 62.733333 | AA12: =R66 -> 68.4
A13: E_AES_256_ECB_10_ZeroBytePadding_1521404543009 | B13: 39 | C13: 48 | D13: 66 | E13: 94 | F13: 80 | G13: 46 | H13: 99 | I13: 72 | J13: 80 | K13: 86 | L13: 70 | M13: 72 | N13: 70 | O13: 77 | P13: 73 | R13: =AVERAGE(B13:Q13) -> 71.466667 | X13: ZERO | Y13: =R7 -> 66.4 | Z13: =R38 -> 63.666667 | AA13: =R69 -> 63.8
A16: Algorithm | B16: Time(milliseconds) | C16: Time(milliseconds) | D16: Time(milliseconds) | E16: Time(milliseconds) | F16: Time(milliseconds) | G16: Time(milliseconds) | H16: Time(milliseconds) | I16: Time(milliseconds) | J16: Time(milliseconds) | K16: Time(milliseconds) | R16: AVG | V16: DECRYPT | Y16: 10 | Z16: 100 | AA16: 200
A17: D_AES_128_CBC_10_PKCS5Padding_1521404635390 | B17: 77 | C17: 31 | D17: 78 | E17: 30 | F17: 31 | G17: 58 | H17: 37 | I17: 30 | J17: 69 | K17: 75 | R17: =AVERAGE(B17:Q17) -> 51.6 | S17: CBC PKCS5 | V17: 128 | W17: ECB | X17: PKCS5 | Y17: =R23 -> 64.8 | Z17: =R54 -> 66 | AA17: =R85 -> 61.2
A18: D_AES_192_CBC_10_PKCS5Padding_1521404635390 | B18: 66 | C18: 59 | D18: 70 | E18: 64 | F18: 86 | G18: 62 | H18: 29 | I18: 76 | J18: 36 | K18: 93 | R18: =AVERAGE(B18:Q18) -> 64.1 | X18: ZERO | Y18: =R26 -> 59.2 | Z18: =R57 -> 62 | AA18: =R88 -> 65.2
A19: D_AES_256_CBC_10_PKCS5Padding_1521404635390 | B19: 73 | C19: 77 | D19: 75 | E19: 88 | F19: 66 | G19: 84 | H19: 24 | I19: 18 | J19: 76 | K19: 82 | R19: =AVERAGE(B19:Q19) -> 66.3 | W19: CBC | X19: PKCS5 | Y19: =R17 -> 51.6 | Z19: =R48 -> 54.7 | AA19: =R79 -> 57.4
A20: D_AES_128_CBC_10_ZeroBytePadding_1521404635390 | B20: 61 | C20: 68 | D20: 73 | E20: 74 | F20: 88 | G20: 81 | H20: 86 | I20: 75 | J20: 88 | K20: 44 | R20: =AVERAGE(B20:Q20) -> 73.8 | S20: CBC ZERO | X20: ZERO | Y20: =R20 -> 73.8 | Z20: =R51 -> 71 | AA20: =R82 -> 58.2
A21: D_AES_192_CBC_10_ZeroBytePadding_1521404635390 | B21: 82 | C21: 47 | D21: 47 | E21: 74 | F21: 74 | G21: 34 | H21: 49 | I21: 64 | J21: 80 | K21: 66 | R21: =AVERAGE(B21:Q21) -> 61.7 | V21: 192 | W21: ECB | X21: PKCS5 | Y21: =R24 -> 61.5 | Z21: =R55 -> 61.5 | AA21: =R86 -> 65.1
A22: D_AES_256_CBC_10_ZeroBytePadding_1521404635390 | B22: 74 | C22: 73 | D22: 27 | E22: 31 | F22: 90 | G22: 56 | H22: 91 | I22: 71 | J22: 87 | K22: 66 | R22: =AVERAGE(B22:Q22) -> 66.6 | X22: ZERO | Y22: =R27 -> 69.4 | Z22: =R58 -> 52.8 | AA22: =R89 -> 65.5
A23: D_AES_128_ECB_10_PKCS5Padding_1521404635390 | B23: 64 | C23: 78 | D23: 82 | E23: 73 | F23: 75 | G23: 24 | H23: 26 | I23: 75 | J23: 71 | K23: 80 | R23: =AVERAGE(B23:Q23) -> 64.8 | S23: ECB PKCS5 | W23: CBC | X23: PKCS5 | Y23: =R18 -> 64.1 | Z23: =R49 -> 74.1 | AA23: =R80 -> 61.4
A24: D_AES_192_ECB_10_PKCS5Padding_1521404635390 | B24: 105 | C24: 72 | D24: 82 | E24: 44 | F24: 72 | G24: 34 | H24: 20 | I24: 75 | J24: 68 | K24: 43 | R24: =AVERAGE(B24:Q24) -> 61.5 | X24: ZERO | Y24: =R21 -> 61.7 | Z24: =R52 -> 66.2 | AA24: =R83 -> 71.8
A25: D_AES_256_ECB_10_PKCS5Padding_1521404635390 | B25: 74 | C25: 29 | D25: 64 | E25: 77 | F25: 67 | G25: 63 | H25: 50 | I25: 55 | J25: 87 | K25: 49 | R25: =AVERAGE(B25:Q25) -> 61.5 | V25: 256 | W25: ECB | X25: PKCS5 | Y25: =R25 -> 61.5 | Z25: =R56 -> 66.4 | AA25: =R87 -> 62.6
A26: D_AES_128_ECB_10_ZeroBytePadding_1521404635390 | B26: 66 | C26: 21 | D26: 48 | E26: 88 | F26: 67 | G26: 25 | H26: 52 | I26: 72 | J26: 82 | K26: 71 | R26: =AVERAGE(B26:Q26) -> 59.2 | S26: ECB Zero | X26: ZERO | Y26: =R28 -> 54.2 | Z26: =R59 -> 67.3 | AA26: =R90 -> 74.3
A27: D_AES_192_ECB_10_ZeroBytePadding_1521404635390 | B27: 61 | C27: 58 | D27: 70 | E27: 88 | F27: 86 | G27: 47 | H27: 43 | I27: 108 | J27: 77 | K27: 56 | R27: =AVERAGE(B27:Q27) -> 69.4 | W27: CBC | X27: PKCS5 | Y27: =R19 -> 66.3 | Z27: =R50 -> 74.1 | AA27: =R81 -> 73.5
A28: D_AES_256_ECB_10_ZeroBytePadding_1521404635390 | B28: 49 | C28: 47 | D28: 43 | E28: 80 | F28: 67 | G28: 57 | H28: 33 | I28: 54 | J28: 68 | K28: 44 | R28: =AVERAGE(B28:Q28) -> 54.2 | X28: ZERO | Y28: =R22 -> 66.6 | Z28: =R53 -> 59.7 | AA28: =R84 -> 65.6
A30: 100
A32: Algorithm | B32: Time(milliseconds) | C32: Time(milliseconds) | D32: Time(milliseconds) | E32: Time(milliseconds) | F32: Time(milliseconds) | G32: Time(milliseconds) | H32: Time(milliseconds) | I32: Time(milliseconds) | J32: Time(milliseconds) | K32: Time(milliseconds) | R32: AVG
A33: E_AES_128_CBC_100_PKCS5Padding_1521404733303 | B33: 54 | C33: 73 | D33: 63 | E33: 50 | F33: 77 | G33: 26 | H33: 49 | I33: 30 | J33: 47 | K33: 83 | L33: 29 | M33: 31 | N33: 79 | O33: 81 | P33: 82 | R33: =AVERAGE(B33:Q33) -> 56.933333 | S33: CBC PKCS5
A34: E_AES_192_CBC_100_PKCS5Padding_1521404733303 | B34: 62 | C34: 76 | D34: 62 | E34: 47 | F34: 107 | G34: 50 | H34: 97 | I34: 47 | J34: 71 | K34: 63 | L34: 62 | M34: 47 | N34: 55 | O34: 65 | P34: 78 | R34: =AVERAGE(B34:Q34) -> 65.933333
A35: E_AES_256_CBC_100_PKCS5Padding_1521404733303 | B35: 23 | C35: 42 | D35: 122 | E35: 86 | F35: 54 | G35: 23 | H35: 58 | I35: 92 | J35: 56 | K35: 63 | L35: 62 | M35: 73 | N35: 78 | O35: 53 | P35: 56 | R35: =AVERAGE(B35:Q35) -> 62.733333
A36: E_AES_128_CBC_100_ZeroBytePadding_1521404733303 | B36: 82 | C36: 59 | D36: 58 | E36: 98 | F36: 103 | G36: 49 | H36: 87 | I36: 52 | J36: 102 | K36: 86 | L36: 93 | M36: 72 | N36: 62 | O36: 65 | P36: 43 | R36: =AVERAGE(B36:Q36) -> 74.066667 | S36: CBC ZERO
A37: E_AES_192_CBC_100_ZeroBytePadding_1521404733303 | B37: 73 | C37: 49 | D37: 28 | E37: 57 | F37: 62 | G37: 23 | H37: 91 | I37: 85 | J37: 89 | K37: 77 | L37: 49 | M37: 74 | N37: 64 | O37: 60 | P37: 54 | R37: =AVERAGE(B37:Q37) -> 62.333333
A38: E_AES_256_CBC_100_ZeroBytePadding_1521404733303 | B38: 77 | C38: 49 | D38: 47 | E38: 59 | F38: 78 | G38: 39 | H38: 43 | I38: 60 | J38: 76 | K38: 75 | L38: 63 | M38: 92 | N38: 70 | O38: 60 | P38: 67 | R38: =AVERAGE(B38:Q38) -> 63.666667
A39: E_AES_128_ECB_100_PKCS5Padding_1521404733303 | B39: 46 | C39: 67 | D39: 54 | E39: 72 | F39: 86 | G39: 45 | H39: 70 | I39: 60 | J39: 67 | K39: 62 | L39: 66 | M39: 62 | N39: 45 | O39: 61 | P39: 77 | R39: =AVERAGE(B39:Q39) -> 62.666667 | S39: ECB PKCS5
A40: E_AES_192_ECB_100_PKCS5Padding_1521404733303 | B40: 49 | C40: 49 | D40: 59 | E40: 43 | F40: 77 | G40: 112 | H40: 38 | I40: 61 | J40: 70 | K40: 67 | L40: 70 | M40: 63 | N40: 48 | O40: 61 | P40: 106 | R40: =AVERAGE(B40:Q40) -> 64.866667
A41: E_AES_256_ECB_100_PKCS5Padding_1521404733303 | B41: 76 | C41: 61 | D41: 31 | E41: 70 | F41: 67 | G41: 31 | H41: 85 | I41: 77 | J41: 62 | K41: 58 | L41: 63 | M41: 56 | N41: 41 | O41: 48 | P41: 115 | R41: =AVERAGE(B41:Q41) -> 62.733333
A42: E_AES_128_ECB_100_ZeroBytePadding_1521404733303 | B42: 105 | C42: 55 | D42: 45 | E42: 53 | F42: 78 | G42: 34 | H42: 36 | I42: 74 | J42: 76 | K42: 82 | L42: 67 | M42: 85 | N42: 52 | O42: 53 | P42: 76 | R42: =AVERAGE(B42:Q42) -> 64.733333 | S42: ECB Zero
A43: E_AES_192_ECB_100_ZeroBytePadding_1521404733303 | B43: 101 | C43: 71 | D43: 74 | E43: 76 | F43: 30 | G43: 81 | H43: 66 | I43: 59 | J43: 61 | K43: 89 | L43: 48 | M43: 49 | N43: 86 | O43: 72 | P43: 90 | R43: =AVERAGE(B43:Q43) -> 70.2
A44: E_AES_256_ECB_100_ZeroBytePadding_1521404733303 | B44: 57 | C44: 48 | D44: 48 | E44: 45 | F44: 90 | G44: 46 | H44: 49 | I44: 61 | J44: 49 | K44: 76 | L44: 40 | M44: 67 | N44: 94 | O44: 90 | P44: 73 | R44: =AVERAGE(B44:Q44) -> 62.2
...

Sheet Comsuption (mJ)
A1: Algorithm | B1: Consumption(mW) | C1: Consumption(mW) | D1: Consumption(mW) | E1: Consumption(mW) | F1: Consumption(mW) | G1: Consumption(mW) | H1: Consumption(mW) | I1: Consumption(mW) | J1: Consumption(mW) | K1: Consumption(mW) | R1: AVG | V1: ENCRYPT | W1: mJ | Y1: 10 | Z1: 100 | AA1: 200 | AC1: ENCRYPT | AD1: mS | AF1: 10 | AG1: 100 | AH1: 200
A2: E_AES_128_CBC_10_PKCS5Padding_1521404543009 | B2: =Comsuption!B2*Time!B2 -> 50 | C2: =Comsuption!C2*Time!C2 -> 0 | D2: =Comsuption!D2*Time!D2 -> 61 | E2: =Comsuption!E2*Time!E2 -> 170 | F2: =Comsuption!F2*Time!F2 -> 52 | G2: =Comsuption!G2*Time!G2 -> 41 | H2: =Comsuption!H2*Time!H2 -> 0 | I2: =Comsuption!I2*Time!I2 -> 0 | ... P2: =Comsuption!P2*Time!P2 -> 0 | R2: =AVERAGE(B2:P2) -> 35.066667 | S2: CBC PKCS5 | T2: 128 | V2: 128 | W2: ECB | X2: PKCS5 | Y2: =R8 -> 16.8 | Z2: =R39 -> 8.6 | AA2: =R70 -> 42.7 | AC2: 128 | AD2: ECB | AE2: PKCS5 | AF2: 61.7 | AG2: 62.9 | AH2: 80.8
A3: E_AES_192_CBC_10_PKCS5Padding_1521404543009 | B3: =Comsuption!B3*Time!B3 -> 67 | C3: =Comsuption!C3*Time!C3 -> 0 | D3: =Comsuption!D3*Time!D3 -> 0 | E3: =Comsuption!E3*Time!E3 -> 0 | F3: =Comsuption!F3*Time!F3 -> 84 | G3: =Comsuption!G3*Time!G3 -> 0 | H3: =Comsuption!H3*Time!H3 -> 0 | I3: =Comsuption!I3*Time!I3 -> 0 | ... P3: =Comsuption!P3*Time!P3 -> 0 | R3: =AVERAGE(B3:P3) -> 10.066667 | T3: 192 | X3: ZERO | Y3: =R11 -> 11.6 | Z3: =R42 -> 45.6 | AA3: =R73 -> 65.4 | AE3: ZERO | AF3: 71.7 | AG3: 63.8 | AH3: 71.5
A4: E_AES_256_CBC_10_PKCS5Padding_1521404543009 | B4: =Comsuption!B4*Time!B4 -> 0 | C4: =Comsuption!C4*Time!C4 -> 0 | D4: =Comsuption!D4*Time!D4 -> 39 | E4: =Comsuption!E4*Time!E4 -> 0 | F4: =Comsuption!F4*Time!F4 -> 0 | G4: =Comsuption!G4*Time!G4 -> 0 | H4: =Comsuption!H4*Time!H4 -> 0 | I4: =Comsuption!I4*Time!I4 -> 0 | ... P4: =Comsuption!P4*Time!P4 -> 0 | R4: =AVERAGE(B4:P4) -> 2.6 | T4: 256 | W4: CBC | X4: PKCS5 | Y4: =R2 -> 35.066667 | Z4: =R33 -> 49.3 | AA4: =R64 -> 38.3 | AD4: CBC | AE4: PKCS5 | AF4: 54.4 | AG4: 55.2 | AH4: 49
A5: E_AES_128_CBC_10_ZeroBytePadding_1521404543009 | B5: =Comsuption!B5*Time!B5 -> 0 | C5: =Comsuption!C5*Time!C5 -> 65 | D5: =Comsuption!D5*Time!D5 -> 0 | E5: =Comsuption!E5*Time!E5 -> 0 | F5: =Comsuption!F5*Time!F5 -> 0 | G5: =Comsuption!G5*Time!G5 -> 56 | H5: =Comsuption!H5*Time!H5 -> 65 | I5: =Comsuption!I5*Time!I5 -> 0 | ... P5: =Comsuption!P5*Time!P5 -> 0 | R5: =AVERAGE(B5:P5) -> 12.4 | S5: CBC ZERO | T5: 128 | X5: ZERO | Y5: =R5 -> 12.4 | Z5: =R36 -> 54 | AA5: =R67 -> 32.3 | AE5: ZERO | AF5: 65.3 | AG5: 77.6 | AH5: 78.7
A6: E_AES_192_CBC_10_ZeroBytePadding_1521404543009 | B6: =Comsuption!B6*Time!B6 -> 0 | C6: =Comsuption!C6*Time!C6 -> 0 | D6: =Comsuption!D6*Time!D6 -> 0 | E6: =Comsuption!E6*Time!E6 -> 72 | F6: =Comsuption!F6*Time!F6 -> 0 | G6: =Comsuption!G6*Time!G6 -> 0 | H6: =Comsuption!H6*Time!H6 -> 0 | I6: =Comsuption!I6*Time!I6 -> 47 | ... P6: =Comsuption!P6*Time!P6 -> 0 | R6: =AVERAGE(B6:P6) -> 20.6 | T6: 192 | V6: 192 | W6: ECB | X6: PKCS5 | Y6: =R9 -> 1.9333333 | Z6: =R40 -> 36 | AA6: =R71 -> 19.8 | AC6: 192 | AD6: ECB | AE6: PKCS5 | AF6: 64.1 | AG6: 62.5 | AH6: 60.8
A7: E_AES_256_CBC_10_ZeroBytePadding_1521404543009 | B7: =Comsuption!B7*Time!B7 -> 0 | C7: =Comsuption!C7*Time!C7 -> 0 | D7: =Comsuption!D7*Time!D7 -> 0 | E7: =Comsuption!E7*Time!E7 -> 114 | F7: =Comsuption!F7*Time!F7 -> 0 | G7: =Comsuption!G7*Time!G7 -> 69 | H7: =Comsuption!H7*Time!H7 -> 0 | I7: =Comsuption!I7*Time!I7 -> 0 | ... P7: =Comsuption!P7*Time!P7 -> 0 | R7: =AVERAGE(B7:P7) -> 16.266667 | T7: 256 | X7: ZERO | Y7: =R12 -> 0 | Z7: =R43 -> 48.4 | AA7: =R74 -> 40.1 | AE7: ZERO | AF7: 65.2 | AG7: 70.8 | AH7: 61.8
A8: E_AES_128_ECB_10_PKCS5Padding_1521404543009 | B8: =Comsuption!B8*Time!B8 -> 0 | C8: =Comsuption!C8*Time!C8 -> 0 | D8: =Comsuption!D8*Time!D8 -> 0 | E8: =Comsuption!E8*Time!E8 -> 170 | F8: =Comsuption!F8*Time!F8 -> 0 | G8: =Comsuption!G8*Time!G8 -> 0 | H8: =Comsuption!H8*Time!H8 -> 0 | I8: =Comsuption!I8*Time!I8 -> 0 | ... P8: =Comsuption!P8*Time!P8 -> 0 | R8: =AVERAGE(B8:P8) -> 16.8 | S8: ECB PKCS5 | T8: 128 | W8: CBC | X8: PKCS5 | Y8: =R3 -> 10.066667 | Z8: =R34 -> 21.6 | AA8: =R65 -> 53.9 | AD8: CBC | AE8: PKCS5 | AF8: 59 | AG8: 68.2 | AH8: 76.5
A9: E_AES_192_ECB_10_PKCS5Padding_1521404543009 | B9: =Comsuption!B9*Time!B9 -> 29 | C9: =Comsuption!C9*Time!C9 -> 0 | D9: =Comsuption!D9*Time!D9 -> 0 | E9: =Comsuption!E9*Time!E9 -> 0 | F9: =Comsuption!F9*Time!F9 -> 0 | G9: =Comsuption!G9*Time!G9 -> 0 | H9: =Comsuption!H9*Time!H9 -> 0 | I9: =Comsuption!I9*Time!I9 -> 0 | ... P9: =Comsuption!P9*Time!P9 -> 0 | R9: =AVERAGE(B9:P9) -> 1.9333333 | T9: 192 | X9: ZERO | Y9: =R6 -> 20.6 | Z9: =R37 -> 46.2 | AA9: =R68 -> 44.1 | AE9: ZERO | AF9: 74.2 | AG9: 63.4 | AH9: 66.8
A10: E_AES_256_ECB_10_PKCS5Padding_1521404543009 | B10: =Comsuption!B10*Time!B10 -> 0 | C10: =Comsuption!C10*Time!C10 -> 64 | D10: =Comsuption!D10*Time!D10 -> 0 | E10: =Comsuption!E10*Time!E10 -> 0 | F10: =Comsuption!F10*Time!F10 -> 0 | G10: =Comsuption!G10*Time!G10 -> 0 | H10: =Comsuption!H10*Time!H10 -> 0 | I10: =Comsuption!I10*Time!I10 -> 0 | ... P10: =Comsuption!P10*Time!P10 -> 0 | R10: =AVERAGE(B10:P10) -> 14.866667 | T10: 256 | V10: 256 | W10: ECB | X10: PKCS5 | Y10: =R10 -> 14.866667 | Z10: =R41 -> 52.8 | AA10: =R72 -> 27.1 | AC10: 256 | AD10: ECB | AE10: PKCS5 | AF10: 72.1 | AG10: 61.8 | AH10: 64.5
A11: E_AES_128_ECB_10_ZeroBytePadding_1521404543009 | B11: =Comsuption!B11*Time!B11 -> 0 | C11: =Comsuption!C11*Time!C11 -> 0 | D11: =Comsuption!D11*Time!D11 -> 0 | E11: =Comsuption!E11*Time!E11 -> 0 | F11: =Comsuption!F11*Time!F11 -> 80 | G11: =Comsuption!G11*Time!G11 -> 0 | H11: =Comsuption!H11*Time!H11 -> 0 | I11: =Comsuption!I11*Time!I11 -> 0 | ... P11: =Comsuption!P11*Time!P11 -> 0 | R11: =AVERAGE(B11:P11) -> 11.6 | S11: ECB Zero | T11: 128 | X11: ZERO | Y11: =R13 -> 6.2666667 | Z11: =R44 -> 41.9 | AA11: =R75 -> 46.8 | AE11: ZERO | AF11: 71 | AG11: 56.9 | AH11: 73.8
A12: E_AES_192_ECB_10_ZeroBytePadding_1521404543009 | B12: =Comsuption!B12*Time!B12 -> 0 | C12: =Comsuption!C12*Time!C12 -> 0 | D12: =Comsuption!D12*Time!D12 -> 0 | E12: =Comsuption!E12*Time!E12 -> 0 | F12: =Comsuption!F12*Time!F12 -> 0 | G12: =Comsuption!G12*Time!G12 -> 0 | H12: =Comsuption!H12*Time!H12 -> 0 | I12: =Comsuption!I12*Time!I12 -> 0 | ... P12: =Comsuption!P12*Time!P12 -> 0 | R12: =AVERAGE(B12:P12) -> 0 | T12: 192 | W12: CBC | X12: PKCS5 | Y12: =R4 -> 2.6 | Z12: =R35 -> 7.7 | AA12: =R66 -> 39.4 | AD12: CBC | AE12: PKCS5 | AF12: 57.2 | AG12: 61.9 | AH12: 70.4
A13: E_AES_256_ECB_10_ZeroBytePadding_1521404543009 | B13: =Comsuption!B13*Time!B13 -> 0 | C13: =Comsuption!C13*Time!C13 -> 0 | D13: =Comsuption!D13*Time!D13 -> 0 | E13: =Comsuption!E13*Time!E13 -> 94 | F13: =Comsuption!F13*Time!F13 -> 0 | G13: =Comsuption!G13*Time!G13 -> 0 | H13: =Comsuption!H13*Time!H13 -> 0 | I13: =Comsuption!I13*Time!I13 -> 0 | ... P13: =Comsuption!P13*Time!P13 -> 0 | R13: =AVERAGE(B13:P13) -> 6.2666667 | T13: 256 | X13: ZERO | Y13: =R7 -> 16.266667 | Z13: =R38 -> 41.2 | AA13: =R69 -> 30.1 | AE13: ZERO | AF13: 64.5 | AG13: 60.3 | AH13: 61.9
A16: Algorithm | B16: Consumption(mW) | C16: Consumption(mW) | D16: Consumption(mW) | E16: Consumption(mW) | F16: Consumption(mW) | G16: Consumption(mW) | H16: Consumption(mW) | I16: Consumption(mW) | J16: Consumption(mW) | K16: Consumption(mW) | R16: AVG | V16: DECRYPT | W16: mJ | Y16: 10 | Z16: 100 | AA16: 200 | AC16: DECRYPT | AD16: mS | AF16: 10 | AG16: 100 | AH16: 200
A17: D_AES_128_CBC_10_PKCS5Padding_1521404635390 | B17: =Comsuption!B17*Time!B17 -> 0 | C17: =Comsuption!C17*Time!C17 -> 62 | D17: =Comsuption!D17*Time!D17 -> 78 | E17: =Comsuption!E17*Time!E17 -> 0 | F17: =Comsuption!F17*Time!F17 -> 31 | G17: =Comsuption!G17*Time!G17 -> 58 | H17: =Comsuption!H17*Time!H17 -> 0 | I17: =Comsuption!I17*Time!I17 -> 0 | ... K17: =Comsuption!K17*Time!K17 -> 0 | R17: =AVERAGE(B17:Q17) -> 22.9 | S17: CBC PKCS5 | V17: 128 | W17: ECB | X17: PKCS5 | Y17: =R23 -> 21.9 | Z17: =R54 -> 32.6 | AA17: =R85 -> 36.4 | AC17: 128 | AD17: ECB | AE17: PKCS5 | AF17: 64.8 | AG17: 66 | AH17: 61.2
A18: D_AES_192_CBC_10_PKCS5Padding_1521404635390 | B18: =Comsuption!B18*Time!B18 -> 66 | C18: =Comsuption!C18*Time!C18 -> 0 | D18: =Comsuption!D18*Time!D18 -> 0 | E18: =Comsuption!E18*Time!E18 -> 0 | F18: =Comsuption!F18*Time!F18 -> 0 | G18: =Comsuption!G18*Time!G18 -> 62 | H18: =Comsuption!H18*Time!H18 -> 0 | I18: =Comsuption!I18*Time!I18 -> 0 | ... K18: =Comsuption!K18*Time!K18 -> 0 | R18: =AVERAGE(B18:Q18) -> 12.8 | X18: ZERO | Y18: =R26 -> 0 | Z18: =R57 -> 30.2 | AA18: =R88 -> 59.6 | AE18: ZERO | AF18: 59.2 | AG18: 62 | AH18: 65.2
A19: D_AES_256_CBC_10_PKCS5Padding_1521404635390 | B19: =Comsuption!B19*Time!B19 -> 73 | C19: =Comsuption!C19*Time!C19 -> 77 | D19: =Comsuption!D19*Time!D19 -> 0 | E19: =Comsuption!E19*Time!E19 -> 0 | F19: =Comsuption!F19*Time!F19 -> 0 | G19: =Comsuption!G19*Time!G19 -> 84 | H19: =Comsuption!H19*Time!H19 -> 0 | I19: =Comsuption!I19*Time!I19 -> 0 | ... K19: =Comsuption!K19*Time!K19 -> 82 | R19: =AVERAGE(B19:Q19) -> 31.6 | W19: CBC | X19: PKCS5 | Y19: =R17 -> 22.9 | Z19: =R48 -> 7.6 | AA19: =R79 -> 11.5 | AD19: CBC | AE19: PKCS5 | AF19: 51.6 | AG19: 54.7 | AH19: 57.4
A20: D_AES_128_CBC_10_ZeroBytePadding_1521404635390 | B20: =Comsuption!B20*Time!B20 -> 0 | C20: =Comsuption!C20*Time!C20 -> 0 | D20: =Comsuption!D20*Time!D20 -> 0 | E20: =Comsuption!E20*Time!E20 -> 0 | F20: =Comsuption!F20*Time!F20 -> 0 | G20: =Comsuption!G20*Time!G20 -> 162 | H20: =Comsuption!H20*Time!H20 -> 0 | I20: =Comsuption!I20*Time!I20 -> 75 | ... K20: =Comsuption!K20*Time!K20 -> 0 | R20: =AVERAGE(B20:Q20) -> 23.7 | S20: CBC ZERO | X20: ZERO | Y20: =R20 -> 23.7 | Z20: =R51 -> 25.8 | AA20: =R82 -> 24.3 | AE20: ZERO | AF20: 73.8 | AG20: 71 | AH20: 58.2
A21: D_AES_192_CBC_10_ZeroBytePadding_1521404635390 | B21: =Comsuption!B21*Time!B21 -> 0 | C21: =Comsuption!C21*Time!C21 -> 0 | D21: =Comsuption!D21*Time!D21 -> 47 | E21: =Comsuption!E21*Time!E21 -> 0 | F21: =Comsuption!F21*Time!F21 -> 0 | G21: =Comsuption!G21*Time!G21 -> 0 | H21: =Comsuption!H21*Time!H21 -> 0 | I21: =Comsuption!I21*Time!I21 -> 0 | ... K21: =Comsuption!K21*Time!K21 -> 0 | R21: =AVERAGE(B21:Q21) -> 4.7 | V21: 192 | W21: ECB | X21: PKCS5 | Y21: =R24 -> 10.5 | Z21: =R55 -> 59.9 | AA21: =R86 -> 38.1 | AC21: 192 | AD21: ECB | AE21: PKCS5 | AF21: 61.5 | AG21: 61.5 | AH21: 65.1
A22: D_AES_256_CBC_10_ZeroBytePadding_1521404635390 | B22: =Comsuption!B22*Time!B22 -> 74 | C22: =Comsuption!C22*Time!C22 -> 73 | D22: =Comsuption!D22*Time!D22 -> 0 | E22: =Comsuption!E22*Time!E22 -> 0 | F22: =Comsuption!F22*Time!F22 -> 0 | G22: =Comsuption!G22*Time!G22 -> 0 | H22: =Comsuption!H22*Time!H22 -> 91 | I22: =Comsuption!I22*Time!I22 -> 71 | ... K22: =Comsuption!K22*Time!K22 -> 66 | R22: =AVERAGE(B22:Q22) -> 37.5 | X22: ZERO | Y22: =R27 -> 4.3 | Z22: =R58 -> 17.3 | AA22: =R89 -> 33.1 | AE22: ZERO | AF22: 69.4 | AG22: 52.8 | AH22: 65.5
A23: D_AES_128_ECB_10_PKCS5Padding_1521404635390 | B23: =Comsuption!B23*Time!B23 -> 0 | C23: =Comsuption!C23*Time!C23 -> 0 | D23: =Comsuption!D23*Time!D23 -> 0 | E23: =Comsuption!E23*Time!E23 -> 219 | F23: =Comsuption!F23*Time!F23 -> 0 | G23: =Comsuption!G23*Time!G23 -> 0 | H23: =Comsuption!H23*Time!H23 -> 0 | I23: =Comsuption!I23*Time!I23 -> 0 | ... K23: =Comsuption!K23*Time!K23 -> 0 | R23: =AVERAGE(B23:Q23) -> 21.9 | S23: ECB PKCS5 | W23: CBC | X23: PKCS5 | Y23: =R18 -> 12.8 | Z23: =R49 -> 66.3 | AA23: =R80 -> 27.1 | AD23: CBC | AE23: PKCS5 | AF23: 64.1 | AG23: 74.1 | AH23: 61.4
A24: D_AES_192_ECB_10_PKCS5Padding_1521404635390 | B24: =Comsuption!B24*Time!B24 -> 105 | C24: =Comsuption!C24*Time!C24 -> 0 | D24: =Comsuption!D24*Time!D24 -> 0 | E24: =Comsuption!E24*Time!E24 -> 0 | F24: =Comsuption!F24*Time!F24 -> 0 | G24: =Comsuption!G24*Time!G24 -> 0 | H24: =Comsuption!H24*Time!H24 -> 0 | I24: =Comsuption!I24*Time!I24 -> 0 | ... K24: =Comsuption!K24*Time!K24 -> 0 | R24: =AVERAGE(B24:Q24) -> 10.5 | X24: ZERO | Y24: =R21 -> 4.7 | Z24: =R52 -> 46 | AA24: =R83 -> 75.4 | AE24: ZERO | AF24: 61.7 | AG24: 66.2 | AH24: 71.8
A25: D_AES_256_ECB_10_PKCS5Padding_1521404635390 | B25: =Comsuption!B25*Time!B25 -> 0 | C25: =Comsuption!C25*Time!C25 -> 29 | D25: =Comsuption!D25*Time!D25 -> 64 | E25: =Comsuption!E25*Time!E25 -> 0 | F25: =Comsuption!F25*Time!F25 -> 0 | G25: =Comsuption!G25*Time!G25 -> 0 | H25: =Comsuption!H25*Time!H25 -> 0 | I25: =Comsuption!I25*Time!I25 -> 0 | ... K25: =Comsuption!K25*Time!K25 -> 0 | R25: =AVERAGE(B25:Q25) -> 9.3 | V25: 256 | W25: ECB | X25: PKCS5 | Y25: =R25 -> 9.3 | Z25: =R56 -> 65.7 | AA25: =R87 -> 67 | AC25: 256 | AD25: ECB | AE25: PKCS5 | AF25: 61.5 | AG25: 66.4 | AH25: 62.6
A26: D_AES_128_ECB_10_ZeroBytePadding_1521404635390 | B26: =Comsuption!B26*Time!B26 -> 0 | C26: =Comsuption!C26*Time!C26 -> 0 | D26: =Comsuption!D26*Time!D26 -> 0 | E26: =Comsuption!E26*Time!E26 -> 0 | F26: =Comsuption!F26*Time!F26 -> 0 | G26: =Comsuption!G26*Time!G26 -> 0 | H26: =Comsuption!H26*Time!H26 -> 0 | I26: =Comsuption!I26*Time!I26 -> 0 | ... K26: =Comsuption!K26*Time!K26 -> 0 | R26: =AVERAGE(B26:Q26) -> 0 | S26: ECB Zero | X26: ZERO | Y26: =R28 -> 4.4 | Z26: =R59 -> 43.3 | AA26: =R90 -> 68.2 | AE26: ZERO | AF26: 54.2 | AG26: 67.3 | AH26: 74.3
A27: D_AES_192_ECB_10_ZeroBytePadding_1521404635390 | B27: =Comsuption!B27*Time!B27 -> 0 | C27: =Comsuption!C27*Time!C27 -> 0 | D27: =Comsuption!D27*Time!D27 -> 0 | E27: =Comsuption!E27*Time!E27 -> 0 | F27: =Comsuption!F27*Time!F27 -> 0 | G27: =Comsuption!G27*Time!G27 -> 0 | H27: =Comsuption!H27*Time!H27 -> 43 | I27: =Comsuption!I27*Time!I27 -> 0 | ... K27: =Comsuption!K27*Time!K27 -> 0 | R27: =AVERAGE(B27:Q27) -> 4.3 | W27: CBC | X27: PKCS5 | Y27: =R19 -> 31.6 | Z27: =R50 -> 29.7 | AA27: =R81 -> 42.7 | AD27: CBC | AE27: PKCS5 | AF27: 66.3 | AG27: 74.1 | AH27: 73.5
A28: D_AES_256_ECB_10_ZeroBytePadding_1521404635390 | B28: =Comsuption!B28*Time!B28 -> 0 | C28: =Comsuption!C28*Time!C28 -> 0 | D28: =Comsuption!D28*Time!D28 -> 0 | E28: =Comsuption!E28*Time!E28 -> 0 | F28: =Comsuption!F28*Time!F28 -> 0 | G28: =Comsuption!G28*Time!G28 -> 0 | H28: =Comsuption!H28*Time!H28 -> 0 | I28: =Comsuption!I28*Time!I28 -> 0 | ... K28: =Comsuption!K28*Time!K28 -> 44 | R28: =AVERAGE(B28:Q28) -> 4.4 | X28: ZERO | Y28: =R22 -> 37.5 | Z28: =R53 -> 73.1 | AA28: =R84 -> 29.7 | AE28: ZERO | AF28: 66.6 | AG28: 59.7 | AH28: 65.6
A30: 100
A32: Algorithm | B32: Consumption(mW) | C32: Consumption(mW) | D32: Consumption(mW) | E32: Consumption(mW) | F32: Consumption(mW) | G32: Consumption(mW) | H32: Consumption(mW) | I32: Consumption(mW) | J32: Consumption(mW) | K32: Consumption(mW) | R32: AVG
A33: E_AES_128_CBC_100_PKCS5Padding_1521404733303 | B33: =Comsuption!B33*Time!B33 -> 54 | C33: =Comsuption!C33*Time!C33 -> 0 | D33: =Comsuption!D33*Time!D33 -> 63 | E33: =Comsuption!E33*Time!E33 -> 50 | F33: =Comsuption!F33*Time!F33 -> 0 | G33: =Comsuption!G33*Time!G33 -> 0 | H33: =Comsuption!H33*Time!H33 -> 0 | I33: =Comsuption!I33*Time!I33 -> 30 | ... K33: =Comsuption!K33*Time!K33 -> 249 | R33: =AVERAGE(B33:Q33) -> 49.3 | S33: CBC PKCS5
A34: E_AES_192_CBC_100_PKCS5Padding_1521404733303 | B34: =Comsuption!B34*Time!B34 -> 62 | C34: =Comsuption!C34*Time!C34 -> 0 | D34: =Comsuption!D34*Time!D34 -> 0 | E34: =Comsuption!E34*Time!E34 -> 47 | F34: =Comsuption!F34*Time!F34 -> 107 | G34: =Comsuption!G34*Time!G34 -> 0 | H34: =Comsuption!H34*Time!H34 -> 0 | I34: =Comsuption!I34*Time!I34 -> 0 | ... K34: =Comsuption!K34*Time!K34 -> 0 | R34: =AVERAGE(B34:Q34) -> 21.6
A35: E_AES_256_CBC_100_PKCS5Padding_1521404733303 | B35: =Comsuption!B35*Time!B35 -> 0 | C35: =Comsuption!C35*Time!C35 -> 0 | D35: =Comsuption!D35*Time!D35 -> 0 | E35: =Comsuption!E35*Time!E35 -> 0 | F35: =Comsuption!F35*Time!F35 -> 54 | G35: =Comsuption!G35*Time!G35 -> 23 | H35: =Comsuption!H35*Time!H35 -> 0 | I35: =Comsuption!I35*Time!I35 -> 0 | ... K35: =Comsuption!K35*Time!K35 -> 0 | R35: =AVERAGE(B35:Q35) -> 7.7
A36: E_AES_128_CBC_100_ZeroBytePadding_1521404733303 | B36: =Comsuption!B36*Time!B36 -> 0 | C36: =Comsuption!C36*Time!C36 -> 59 | D36: =Comsuption!D36*Time!D36 -> 58 | E36: =Comsuption!E36*Time!E36 -> 98 | F36: =Comsuption!F36*Time!F36 -> 103 | G36: =Comsuption!G36*Time!G36 -> 49 | H36: =Comsuption!H36*Time!H36 -> 87 | I36: =Comsuption!I36*Time!I36 -> 0 | ... K36: =Comsuption!K36*Time!K36 -> 86 | R36: =AVERAGE(B36:Q36) -> 54 | S36: CBC ZERO
A37: E_AES_192_CBC_100_ZeroBytePadding_1521404733303 | B37: =Comsuption!B37*Time!B37 -> 146 | C37: =Comsuption!C37*Time!C37 -> 0 | D37: =Comsuption!D37*Time!D37 -> 28 | E37: =Comsuption!E37*Time!E37 -> 0 | F37: =Comsuption!F37*Time!F37 -> 0 | G37: =Comsuption!G37*Time!G37 -> 23 | H37: =Comsuption!H37*Time!H37 -> 91 | I37: =Comsuption!I37*Time!I37 -> 85 | ... K37: =Comsuption!K37*Time!K37 -> 0 | R37: =AVERAGE(B37:Q37) -> 46.2
A38: E_AES_256_CBC_100_ZeroBytePadding_1521404733303 | B38: =Comsuption!B38*Time!B38 -> 154 | C38: =Comsuption!C38*Time!C38 -> 49 | D38: =Comsuption!D38*Time!D38 -> 47 | E38: =Comsuption!E38*Time!E38 -> 59 | F38: =Comsuption!F38*Time!F38 -> 0 | G38: =Comsuption!G38*Time!G38 -> 0 | H38: =Comsuption!H38*Time!H38 -> 43 | I38: =Comsuption!I38*Time!I38 -> 60 | ... K38: =Comsuption!K38*Time!K38 -> 0 | R38: =AVERAGE(B38:Q38) -> 41.2
A39: E_AES_128_ECB_100_PKCS5Padding_1521404733303 | B39: =Comsuption!B39*Time!B39 -> 0 | C39: =Comsuption!C39*Time!C39 -> 0 | D39: =Comsuption!D39*Time!D39 -> 0 | E39: =Comsuption!E39*Time!E39 -> 0 | F39: =Comsuption!F39*Time!F39 -> 86 | G39: =Comsuption!G39*Time!G39 -> 0 | H39: =Comsuption!H39*Time!H39 -> 0 | I39: =Comsuption!I39*Time!I39 -> 0 | ... K39: =Comsuption!K39*Time!K39 -> 0 | R39: =AVERAGE(B39:Q39) -> 8.6 | S39: ECB PKCS5
A40: E_AES_192_ECB_100_PKCS5Padding_1521404733303 | B40: =Comsuption!B40*Time!B40 -> 98 | C40: =Comsuption!C40*Time!C40 -> 0 | D40: =Comsuption!D40*Time!D40 -> 0 | E40: =Comsuption!E40*Time!E40 -> 0 | F40: =Comsuption!F40*Time!F40 -> 0 | G40: =Comsuption!G40*Time!G40 -> 224 | H40: =Comsuption!H40*Time!H40 -> 38 | I40: =Comsuption!I40*Time!I40 -> 0 | ... K40: =Comsuption!K40*Time!K40 -> 0 | R40: =AVERAGE(B40:Q40) -> 36
A41: E_AES_256_ECB_100_PKCS5Padding_1521404733303 | B41: =Comsuption!B41*Time!B41 -> 304 | C41: =Comsuption!C41*Time!C41 -> 0 | D41: =Comsuption!D41*Time!D41 -> 0 | E41: =Comsuption!E41*Time!E41 -> 0 | F41: =Comsuption!F41*Time!F41 -> 0 | G41: =Comsuption!G41*Time!G41 -> 62 | H41: =Comsuption!H41*Time!H41 -> 85 | I41: =Comsuption!I41*Time!I41 -> 77 | ... K41: =Comsuption!K41*Time!K41 -> 0 | R41: =AVERAGE(B41:Q41) -> 52.8
A42: E_AES_128_ECB_100_ZeroBytePadding_1521404733303 | B42: =Comsuption!B42*Time!B42 -> 210 | C42: =Comsuption!C42*Time!C42 -> 55 | D42: =Comsuption!D42*Time!D42 -> 45 | E42: =Comsuption!E42*Time!E42 -> 0 | F42: =Comsuption!F42*Time!F42 -> 78 | G42: =Comsuption!G42*Time!G42 -> 68 | H42: =Comsuption!H42*Time!H42 -> 0 | I42: =Comsuption!I42*Time!I42 -> 0 | ... K42: =Comsuption!K42*Time!K42 -> 0 | R42: =AVERAGE(B42:Q42) -> 45.6 | S42: ECB Zero
A43: E_AES_192_ECB_100_ZeroBytePadding_1521404733303 | B43: =Comsuption!B43*Time!B43 -> 202 | C43: =Comsuption!C43*Time!C43 -> 0 | D43: =Comsuption!D43*Time!D43 -> 0 | E43: =Comsuption!E43*Time!E43 -> 0 | F43: =Comsuption!F43*Time!F43 -> 0 | G43: =Comsuption!G43*Time!G43 -> 162 | H43: =Comsuption!H43*Time!H43 -> 0 | I43: =Comsuption!I43*Time!I43 -> 59 | ... K43: =Comsuption!K43*Time!K43 -> 0 | R43: =AVERAGE(B43:Q43) -> 48.4
A44: E_AES_256_ECB_100_ZeroBytePadding_1521404733303 | B44: =Comsuption!B44*Time!B44 -> 114 | C44: =Comsuption!C44*Time!C44 -> 0 | D44: =Comsuption!D44*Time!D44 -> 0 | E44: =Comsuption!E44*Time!E44 -> 45 | F44: =Comsuption!F44*Time!F44 -> 0 | G44: =Comsuption!G44*Time!G44 -> 184 | H44: =Comsuption!H44*Time!H44 -> 0 | I44: =Comsuption!I44*Time!I44 -> 0 | ... K44: =Comsuption!K44*Time!K44 -> 76 | R44: =AVERAGE(B44:Q44) -> 41.9
...

Sheet Consumption_RSA
A1: Algorithm | B1: Consumption(mW) | C1: Consumption(mW) | D1: Consumption(mW) | E1: Consumption(mW) | F1: Consumption(mW) | G1: Consumption(mW) | H1: Consumption(mW) | I1: Consumption(mW) | J1: Consumption(mW) | K1: Consumption(mW) | M1: AVG
A2: E_RSA_512_NONE_10_NoPadding_1521405113235 | B2: 0 | C2: 1 | D2: 0 | E2: 0 | F2: 0 | G2: 0 | H2: 0 | I2: 0 | J2: 0 | K2: 0 | M2: =AVERAGE(B2:L2) -> 0.1
A4: Algorithm | B4: Consumption(mW) | C4: Consumption(mW) | D4: Consumption(mW) | E4: Consumption(mW) | F4: Consumption(mW) | G4: Consumption(mW) | H4: Consumption(mW) | I4: Consumption(mW) | J4: Consumption(mW) | K4: Consumption(mW) | M4: AVG
A5: D_RSA_512_NONE_10_NoPadding_1521405132177 | B5: 4 | C5: 4 | D5: 1 | E5: 1 | F5: 1 | G5: 1 | H5: 3 | I5: 2 | J5: 1 | K5: 1 | M5: =AVERAGE(B5:L5) -> 1.9
A7: 100
A9: Algorithm | B9: Consumption(mW) | C9: Consumption(mW) | D9: Consumption(mW) | E9: Consumption(mW) | F9: Consumption(mW) | G9: Consumption(mW) | H9: Consumption(mW) | I9: Consumption(mW) | J9: Consumption(mW) | K9: Consumption(mW) | M9: AVG
A10: E_RSA_512_NONE_100_NoPadding_1521405149456 | B10: 0 | C10: 0 | D10: 0 | E10: 0 | F10: 0 | G10: 0 | H10: 1 | I10: 1 | J10: 0 | K10: 0 | M10: =AVERAGE(B10:L10) -> 0.2
A12: Algorithm | B12: Consumption(mW) | C12: Consumption(mW) | D12: Consumption(mW) | E12: Consumption(mW) | F12: Consumption(mW) | G12: Consumption(mW) | H12: Consumption(mW) | I12: Consumption(mW) | J12: Consumption(mW) | K12: Consumption(mW) | M12: AVG
A13: D_RSA_512_NONE_100_NoPadding_1521405167474 | B13: 2 | C13: 1 | D13: 2 | E13: 1 | F13: 2 | G13: 2 | H13: 2 | I13: 2 | J13: 2 | K13: 2 | M13: =AVERAGE(B13:L13) -> 1.8

Sheet Time_RSA
A1: Algorithm | B1: Time(milliseconds) | C1: Time(milliseconds) | D1: Time(milliseconds) | E1: Time(milliseconds) | F1: Time(milliseconds) | G1: Time(milliseconds) | H1: Time(milliseconds) | I1: Time(milliseconds) | J1: Time(milliseconds) | K1: Time(milliseconds) | M1: AVG | O1: Encryption | P1: Time | Q1: Consupmtion | T1: Encryption | U1: Time | V1: Consumption | Z1: Encryption | AB1: Decryption
A2: E_RSA_512_NONE_10_NoPadding_1521405113235 | B2: 84 | C2: 49 | D2: 46 | E2: 79 | F2: 77 | G2: 42 | H2: 56 | I2: 46 | J2: 49 | K2: 62 | M2: =AVERAGE(B2:L2) -> 59 | O2: 10 | P2: =M2 -> 59 | Q2: =Consumption_RSA!M2 -> 0.1 | T2: 10 | U2: 59 | V2: =Q2*P2 -> 5.9 | Y2: Data length (bytes) | Z2: Time (mS) | AA2: Consumption (mJ) | AB2: Time (mS) | AC2: Consumption (mJ)
O3: 100 | P3: =M10 -> 53.6 | Q3: =Consumption_RSA!M10 -> 0.2 | T3: 100 | U3: 53.6 | V3: =Q3*P3 -> 10.72 | Y3: 10 | Z3: 59 | AA3: 5.9 | AB3: 76.1 | AC3: 144.59
A4: Algorithm | B4: Time(milliseconds) | C4: Time(milliseconds) | D4: Time(milliseconds) | E4: Time(milliseconds) | F4: Time(milliseconds) | G4: Time(milliseconds) | H4: Time(milliseconds) | I4: Time(milliseconds) | J4: Time(milliseconds) | K4: Time(milliseconds) | M4: AVG | Y4: 100 | Z4: 53.6 | AA4: 10.72 | AB4: 77.2 | AC4: 138.96
A5: D_RSA_512_NONE_10_NoPadding_1521405132177 | B5: 94 | C5: 81 | D5: 65 | E5: 69 | F5: 73 | G5: 65 | H5: 85 | I5: 84 | J5: 82 | K5: 63 | M5: =AVERAGE(B5:L5) -> 76.1
O6: Decryption | T6: Decryption
A7: 100 | O7: 10 | P7: =M5 -> 76.1 | Q7: =Consumption_RSA!M5 -> 1.9 | T7: 10 | U7: 76.1 | V7: =Q7*P7 -> 144.59
O8: 100 | P8: =M13 -> 77.2 | Q8: =Consumption_RSA!M13 -> 1.8 | T8: 100 | U8: 77.2 | V8: =Q8*P8 -> 138.96
A9: Algorithm | B9: Time(milliseconds) | C9: Time(milliseconds) | D9: Time(milliseconds) | E9: Time(milliseconds) | F9: Time(milliseconds) | G9: Time(milliseconds) | H9: Time(milliseconds) | I9: Time(milliseconds) | J9: Time(milliseconds) | K9: Time(milliseconds) | M9: AVG
A10: E_RSA_512_NONE_100_NoPadding_1521405149456 | B10: 63 | C10: 56 | D10: 44 | E10: 49 | F10: 48 | G10: 69 | H10: 62 | I10: 47 | J10: 49 | K10: 49 | M10: =AVERAGE(B10:L10) -> 53.6 | Q10: mW | T10: mJ
A12: Algorithm | B12: Time(milliseconds) | C12: Time(milliseconds) | D12: Time(milliseconds) | E12: Time(milliseconds) | F12: Time(milliseconds) | G12: Time(milliseconds) | H12: Time(milliseconds) | I12: Time(milliseconds) | J12: Time(milliseconds) | K12: Time(milliseconds) | M12: AVG
A13: D_RSA_512_NONE_100_NoPadding_1521405167474 | B13: 68 | C13: 58 | D13: 64 | E13: 64 | F13: 133 | G13: 72 | H13: 70 | I13: 102 | J13: 74 | K13: 67 | M13: =AVERAGE(B13:L13) -> 77.2

Sheet Time_WIFI
A1: 10 | D1: 100 | G1: 1000 | J1: 2000
A2: Algorithm | B2: Time(milliseconds) | D2: Algorithm | E2: Time(milliseconds) | G2: Algorithm | H2: Time(milliseconds) | J2: Algorithm | K2: Time(milliseconds)
A3: W_S_10_1521405775789 | B3: 1161 | D3: W_S_100_1521405235867 | E3: 72 | G3: W_S_1000_1521405248051 | H3: 162 | J3: W_S_2000_1521405258690 | K3: 63
A4: W_S_10_1521405938103 | B4: 142 | D4: W_S_100_1521405949124 | E4: 174 | G4: W_S_1000_1521405961550 | H4: 161 | J4: W_S_2000_1521405973605 | K4: 189
A5: W_S_10_1521405984993 | B5: 180 | D5: W_S_100_1521406033242 | E5: 140 | G5: W_S_1000_1521406090104 | H5: 54 | J5: W_S_2000_1521406156227 | K5: 81
A6: W_S_10_1521405993139 | B6: 125 | D6: W_S_100_1521406049846 | E6: 105 | G6: W_S_1000_1521406108791 | H6: 66 | J6: W_S_2000_1521406166133 | K6: 160
A7: W_S_10_1521406002101 | B7: 124 | D7: W_S_100_1521406057933 | E7: 174 | G7: W_S_1000_1521406121180 | H7: 151 | J7: W_S_2000_1521406174618 | K7: 42
A8: W_S_10_1521406012051 | B8: 103 | D8: W_S_100_1521406068787 | E8: 154 | G8: W_S_1000_1521406131652 | H8: 106 | J8: W_S_2000_1521406186231 | K8: 175
A9: W_S_10_1521406023314 | B9: 71 | D9: W_S_100_1521406079522 | E9: 202 | G9: W_S_1000_1521406141449 | H9: 96 | J9: W_S_2000_1521406195701 | K9: 69
A10: W_S_10_1521408917231 | B10: 140 | D10: W_S_100_1521408943436 | E10: 155 | G10: W_S_1000_1521408968906 | H10: 170 | J10: W_S_2000_1521408995019 | K10: 159
A11: W_S_10_1521408925988 | B11: 166 | D11: W_S_100_1521408951284 | E11: 60 | G11: W_S_1000_1521408976880 | H11: 152 | J11: W_S_2000_1521409010407 | K11: 179
A12: W_S_10_1521408933883 | B12: 150 | D12: W_S_100_1521408959214 | E12: 169 | G12: W_S_1000_1521408984827 | H12: 178 | J12: W_S_2000_1521409019313 | K12: 161
A15: AVG | B15: =AVERAGE(B4:B12) -> 133.44444 | D15: AVG | E15: =AVERAGE(E3:E12) -> 140.5 | G15: AVG | H15: =AVERAGE(H3:H12) -> 129.6 | J15: AVG | K15: =AVERAGE(K3:K12) -> 127.8

Sheet Consumption_WIFI
A1: 10 | F1: 100 | K1: 1000 | P1: 2000
A2: Algorithm | B2: Consumptiom Processador(mW) | C2: Consumption Wifi(mW) | F2: Algorithm | G2: Consumptiom Processador(mW) | H2: Consumption Wifi(mW) | K2: Algorithm | L2: Consumptiom Processador(mW) | M2: Consumption Wifi(mW) | P2: Algorithm | Q2: Consumptiom Processador(mW) | R2: Consumption Wifi(mW)
A3: W_S_10_1521405775789 | B3: 1 | C3: =34 -> 34 | D3: =C3+B3 -> 35 | F3: W_S_100_1521405235867 | G3: 0 | H3: 34 | I3: =H3+G3 -> 34 | K3: W_S_1000_1521405248051 | L3: 0 | M3: 34 | N3: =M3+L3 -> 34 | P3: W_S_2000_1521405258690 | Q3: 0 | R3: 34 | S3: =R3+Q3 -> 34
A4: W_S_10_1521405938103 | B4: 1 | C4: 34 | D4: =C4+B4 -> 35 | F4: W_S_100_1521405949124 | G4: 0 | H4: 34 | I4: =H4+G4 -> 34 | K4: W_S_1000_1521405961550 | L4: 1 | M4: 34 | N4: =M4+L4 -> 35 | P4: W_S_2000_1521405973605 | Q4: 0 | R4: 34 | S4: =R4+Q4 -> 34
A5: W_S_10_1521405984993 | B5: 0 | C5: 34 | D5: =C5+B5 -> 34 | F5: W_S_100_1521406033242 | G5: 0 | H5: 34 | I5: =H5+G5 -> 34 | K5: W_S_1000_1521406090104 | L5: 0 | M5: 34 | N5: =M5+L5 -> 34 | P5: W_S_2000_1521406156227 | Q5: 2 | R5: 34 | S5: =R5+Q5 -> 36
A6: W_S_10_1521405993139 | B6: 1 | C6: 34 | D6: =C6+B6 -> 35 | F6: W_S_100_1521406049846 | G6: 0 | H6: 34 | I6: =H6+G6 -> 34 | K6: W_S_1000_1521406108791 | L6: 1 | M6: 34 | N6: =M6+L6 -> 35 | P6: W_S_2000_1521406166133 | Q6: 0 | R6: 34 | S6: =R6+Q6 -> 34
A7: W_S_10_1521406002101 | B7: 1 | C7: 34 | D7: =C7+B7 -> 35 | F7: W_S_100_1521406057933 | G7: 1 | H7: 34 | I7: =H7+G7 -> 35 | K7: W_S_1000_1521406121180 | L7: 0 | M7: 34 | N7: =M7+L7 -> 34 | P7: W_S_2000_1521406174618 | Q7: 1 | R7: 34 | S7: =R7+Q7 -> 35
A8: W_S_10_1521406012051 | B8: 1 | C8: 34 | D8: =C8+B8 -> 35 | F8: W_S_100_1521406068787 | G8: 0 | H8: 34 | I8: =H8+G8 -> 34 | K8: W_S_1000_1521406131652 | L8: 0 | M8: 34 | N8: =M8+L8 -> 34 | P8: W_S_2000_1521406186231 | Q8: 0 | R8: 34 | S8: =R8+Q8 -> 34
A9: W_S_10_1521406023314 | B9: 1 | C9: 34 | D9: =C9+B9 -> 35 | F9: W_S_100_1521406079522 | G9: 1 | H9: 34 | I9: =H9+G9 -> 35 | K9: W_S_1000_1521406141449 | L9: 0 | M9: 34 | N9: =M9+L9 -> 34 | P9: W_S_2000_1521406195701 | Q9: 1 | R9: 34 | S9: =R9+Q9 -> 35
A10: W_S_10_1521408917231 | B10: 0 | C10: 34 | D10: =C10+B10 -> 34 | F10: W_S_100_1521408943436 | G10: 0 | H10: 34 | I10: =H10+G10 -> 34 | K10: W_S_1000_1521408968906 | L10: 0 | M10: 34 | N10: =M10+L10 -> 34 | P10: W_S_2000_1521408995019 | Q10: 1 | R10: 34 | S10: =R10+Q10 -> 35
A11: W_S_10_1521408925988 | B11: 0 | C11: 34 | D11: =C11+B11 -> 34 | F11: W_S_100_1521408951284 | G11: 0 | H11: 34 | I11: =H11+G11 -> 34 | K11: W_S_1000_1521408976880 | L11: 0 | M11: 34 | N11: =M11+L11 -> 34 | P11: W_S_2000_1521409010407 | Q11: 0 | R11: 34 | S11: =R11+Q11 -> 34
A12: W_S_10_1521408933883 | B12: 1 | C12: 34 | D12: =C12+B12 -> 35 | F12: W_S_100_1521408959214 | G12: 0 | H12: 34 | I12: =H12+G12 -> 34 | K12: W_S_1000_1521408984827 | L12: 1 | M12: 34 | N12: =M12+L12 -> 35 | P12: W_S_2000_1521409019313 | Q12: 0 | R12: 34 | S12: =R12+Q12 -> 34
C15: AVG | D15: =AVERAGE(D3:D12) -> 34.7 | H15: AVG | I15: =AVERAGE(I3:I12) -> 34.2 | M15: AVG | N15: =AVERAGE(N3:N12) -> 34.3 | R15: AVG | S15: =AVERAGE(S3:S12) -> 34.5
D19: Time (mS) | E19: Consumption(mW) | H19: Time (mS) | I19: Consumption(mJ)
C20: 10 | D20: =Time_WIFI!B15 -> 133.44444 | E20: =D15 -> 34.7 | G20: 10 | H20: 133.44444 | I20: =D20*E20 -> 4630.5222
C21: 100 | D21: =Time_WIFI!E15 -> 140.5 | E21: =I15 -> 34.2 | G21: 100 | H21: 140.5 | I21: =D21*E21 -> 4805.1
C22: 1000 | D22: =Time_WIFI!H15 -> 129.6 | E22: =N15 -> 34.3 | G22: 1000 | H22: 129.6 | I22: =D22*E22 -> 4445.28
C23: 2000 | D23: =Time_WIFI!K15 -> 127.8 | E23: =S15 -> 34.5 | G23: 2000 | H23: 127.8 | I23: =D23*E23 -> 4409.1
